Workbook

Sheet Petunjuk
A1: Petunjuk Lembar Kerja Astronomi Islam Jilid 2
A2: Lembar kerja ini mengikuti Praktik Excel di buku. Sel berlatar kuning dengan angka biru adalah masukan; sel lain berisi rumus dan tidak perlu diubah. Beberapa sheet saling terhubung, jadi isilah menurut alur di bawah.
A3: Peta sheet dan hubungannya
A4: Sheet | B4: Bab | C4: Isi | D4: Hubungan | E4: Sumber rumus | F4: Ketelitian
A5: Kalender | B5: Bab 1 | C5: Tanggal Masehi → Julian Day, hari, pasaran, tanggal Hijriyah urfi. | D5: Berdiri sendiri. | E5: Julian Day: Meeus (1998, bab 7); hari dan pasaran dari JD | F5: Pasti (aturan hitung)
A6: FaseBulan | B6: Bab 2 | C6: Umur, elongasi, dan iluminasi Bulan dari ijtimak rata-rata. | D6: Berdiri sendiri. | E6: Bulan sinodis rata-rata 29,530589 hari; elongasi dan iluminasi pendekatan | F6: Perkiraan kasar, galat beberapa jam pada umur Bulan
A7: Bulan | B7: Bab 3 | C7: Posisi Bulan (60 + 60 suku Meeus). | D7: B4 dan B5 otomatis diambil dari DataHilal. | E7: Teori ELP-2000/82 (Chapront-Touzé & Chapront, Biro Bujur Paris, 1983), versi 60 + 60 suku dari Meeus (1998, bab 47) | F7: Bujur Bulan sekitar 10″, lintang sekitar 4″
A8: KoreksiHilal | B8: Bab 4 | C8: Tangga koreksi tinggi hilal. | D8: Berdiri sendiri; masukan boleh disalin dari DataHilal. | E8: Paralaks dari jarak Bulan; refraksi Sæmundsson (1986); kerendahan ufuk 1,76′√H | F8: Baik untuk udara standar; refraksi nyata dekat ufuk bisa berbeda 0,1°–0,5°
A9: Ijtimak | B9: Bab 5 | C9: Saat ijtimak (Meeus). Masukan: tahun desimal B4, atau bulan Hijriyah di B23–B24. | D9: Dipakai DataHilal (umur Bulan dan tanggal pengamatan). | E9: Meeus (1998, bab 49): ijtimak rata-rata + 25 suku periodik + 14 suku planet | F9: Contoh Syawal 1447 H berselisih 7 detik dari BMKG
A10: Urfi | B10: Bab 6 | C10: Tanggal Hijriyah urfi → Masehi. | D10: Berdiri sendiri. | E10: Kalender Hijriyah tabular (siklus 30 tahun, 11 kabisat, pola II) dari tradisi zij Islam | F10: Pasti; tanggal urfi bisa berbeda 1–2 hari dari awal bulan sebenarnya
A11: DataHilal | B11: Bab 7 | C11: Data hilal saat Matahari terbenam. Masukan: lokasi B4–B7, tanggal B8–B10, ΔT B11. | D11: Memakai Bulan dan Ijtimak; dibaca Kriteria dan Rukyat. | E11: Matahari: algoritma NOAA (Meeus 1998, bab 25); Bulan: sheet Bulan; paralaks dan kerendahan ufuk | F11: Terbenam Matahari 1 detik, terbenam Bulan 6 detik, elongasi di bawah 0,05° dari BMKG
A12: Kriteria | B12: Bab 8 | C12: Hasil wujudul hilal, MABIMS, Danjon, Odeh, Yallop, Turki 2016. | D12: Membaca DataHilal; tanpa masukan. | E12: Wujudul hilal, MABIMS lama dan baru (2021), Danjon (1932), Odeh (2004), Yallop (1997), Turki 2016 | F12: Tergantung data hilal; kasus di dekat batas kriteria perlu dicocokkan dengan data resmi
A13: Rukyat | B13: Bab 11 | C13: Posisi hilal setiap 4 menit sesudah Matahari terbenam. | D13: Membaca DataHilal; masukan hanya koefisien ekstingsi B8. | E13: Massa udara Kasten & Young (1989); ekstingsi dengan koefisien k | F13: Perkiraan; koefisien ekstingsi dipilih sendiri
A14: Gerhana | B14: Bab 13 | C14: Prediksi gerhana (Meeus). Masukan: perkiraan tanggal B4–B6, jenis B7. | D14: Hasilnya disalin ke GerhanaBulan. | E14: Meeus (1998, bab 54): γ, u, magnitudo, dan setengah fase | F14: Jenis gerhana hampir selalu benar; puncak dan kontak berselisih beberapa menit dari NASA
A15: GerhanaBulan | B15: Bab 14 | C15: Jam kontak gerhana Bulan. | D15: Masukan B4–B7 disalin dari Gerhana!B24 dan B36–B38. | E15: Meeus (1998, bab 54): γ, u, magnitudo, dan setengah fase | F15: Jenis gerhana hampir selalu benar; puncak dan kontak berselisih beberapa menit dari NASA
A16: GerhanaMatahari | B16: Bab 15 | C16: Magnitudo dan obskurasi di suatu tempat. | D16: Masukan dari SIM II-15.2. | E16: Geometri dua lingkaran yang beririsan | F16: Pasti, asalkan semidiameter dan jarak sudut benar (dari aplikasi)
A17: Alur A. Menentukan awal bulan Hijriyah (contoh: Jumadilawal 1448 H di UIN SGD Bandung)
A18: 1. Sheet Ijtimak: isi B23 = 1448 dan B24 = 5 (Jumadilawal). B25 memberi k = 331 dan B26 memberi tahun desimal 2026,7615. Ketik 2026,7615 di B4, atau isi B4 dengan rumus =B26 supaya selalu mengikuti B23–B24.
A19: 2. Baca Ijtimak!B20: ijtimak Sabtu, 10 Oktober 2026 pukul 22.50 WIB. Ini ijtimak yang mengawali Jumadilawal.
A20: 3. Sheet DataHilal: isi lokasi di B4–B7 bila bukan UIN SGD Bandung. Lihat B60 (tanggal rukyat yang disarankan): 11/10/2026. Karena ijtimak terjadi sesudah Matahari terbenam pada 10 Oktober, pengamatan dilakukan sore berikutnya. Isi B8 = 2026, B9 = 10, B10 = 11.
A21: 4. Periksa DataHilal: Matahari terbenam 17.45.53 WIB (B32), tinggi hilal toposentris 5,37° (B41), elongasi geosentris 10,36° (B47), umur Bulan 18,9 jam (B52). Umur harus positif; bila negatif, tanggal pengamatan terlalu awal.
A22: 5. Sheet Kriteria: wujudul hilal, MABIMS lama, MABIMS baru, Danjon, dan Turki 2016 terpenuhi; Odeh zona B. Bila kriteria yang dipakai terpenuhi, tanggal 1 jatuh keesokan harinya: 1 Jumadilawal 1448 H = Senin, 12 Oktober 2026. Bila tidak terpenuhi, bulan sebelumnya digenapkan 30 hari, sehingga tanggal 1 jatuh lusa.
A23: 6. Sheet Rukyat: tabel tinggi hilal dan sisa cahayanya setiap 4 menit untuk panduan pengamat.
A24: Mencari tahun desimal sendiri
A25: Tahun desimal = tahun + (nomor hari dalam tahun − 0,5)/365,25. Contoh: 9 Desember 2026 adalah hari ke-343, jadi 2026 + 342,5/365,25 = 2026,94. Tidak perlu teliti: rumus B8 membulatkan k ke bilangan bulat terdekat, sehingga tanggal mana pun dalam rentang sekitar satu minggu dari ijtimak memberi hasil yang sama. Bila yang diketahui adalah bulan Hijriyahnya, lebih mudah memakai B23–B24.
A26: Nomor bulan Hijriyah: 1 Muharam, 2 Safar, 3 Rabiulawal, 4 Rabiulakhir, 5 Jumadilawal, 6 Jumadilakhir, 7 Rajab, 8 Syakban, 9 Ramadan, 10 Syawal, 11 Zulkaidah, 12 Zulhijah.
A27: Alur B. Konversi tanggal
A28: Masehi ke Hijriyah urfi: sheet Kalender (B4–B8). Hijriyah urfi ke Masehi: sheet Urfi (B4–B6). Tanggal urfi hanya perkiraan; awal bulan yang sebenarnya ditentukan dengan Alur A.
... A40: Kesimpulan: cukup akurat untuk belajar dan memeriksa data hilal resmi. Untuk keputusan resmi tetap dipakai data lembaga berwenang yang memakai teori lengkap. Rujukan utama: Meeus, J. (1998). Astronomical Algorithms (ed. ke-2). Richmond: Willmann-Bell.

Sheet Kalender
A1: Kalender | B1: Konversi tanggal Masehi ke Julian Day, hari, pasaran, dan tanggal Hijriyah urfi.
A2: Sumber rumus: Julian Day: Meeus (1998, bab 7); hari dan pasaran dari JD. Ketelitian: Pasti (aturan hitung).
A3: Masukan | B3: Nilai
A4: Tahun (Y) | B4: 2026
A5: Bulan (M) | B5: 12
A6: Tanggal (D) | B6: 9
A7: Jam lokal (jam desimal) | B7: 18
A8: Zona waktu (UTC+) | B8: 7
A10: Jam UT | B10: =B7-B8
A11: Y' | B11: =IF(B5<=2,B4-1,B4)
A12: M' | B12: =IF(B5<=2,B5+12,B5)
A13: A | B13: =INT(B11/100)
A14: B (koreksi Gregorius) | B14: =IF(B4*10000+B5*100+B6>=15821015,2-B13+INT(B13/4),0)
A15: JD tengah malam (00.00 UT) | B15: =INT(365.25*(B11+4716))+INT(30.6001*(B12+1))+B6+B14-1524.5
A16: JD | B16: =B15+B10/24
A17: Nomor hari | B17: =MOD(INT(B15+1.5),7)
A18: Hari | B18: =CHOOSE(B17+1,"Ahad","Senin","Selasa","Rabu","Kamis","Jumat","Sabtu")
A19: Nomor pasaran | B19: =MOD(INT(B15+0.5),5)
A20: Pasaran | B20: =CHOOSE(B19+1,"Legi","Pahing","Pon","Wage","Kliwon")
A22: N = hari sejak 1 Muharam 1 H | B22: =INT(B15+0.5)-1948440
A23: Tahun Hijriyah | B23: =INT((30*B22+10646)/10631)
A24: Hari ke- dalam tahun (mulai 0) | B24: =B22-(354*(B23-1)+INT((3+11*B23)/30))
A25: Bulan Hijriyah | B25: =MIN(12,INT(B24/29.5)+1)
A26: Tanggal Hijriyah | B26: =B24-(29*(B25-1)+INT(B25/2))+1
A27: Nama bulan | B27: =CHOOSE(B25,"Muharam","Safar","Rabiulawal","Rabiulakhir","Jumadilawal","Jumadilakhir","Rajab","Syakban","Ramadan","Syawal","Zulkaidah","Zulhijah")
A28: Tanggal Hijriyah (urfi) | B28: =B26&" "&B27&" "&B23&" H"

Sheet FaseBulan
A1: FaseBulan | B1: Perkiraan umur, elongasi, dan iluminasi Bulan dari ijtimak rata-rata.
A2: Sumber rumus: Bulan sinodis rata-rata 29,530589 hari; elongasi dan iluminasi pendekatan. Ketelitian: Perkiraan kasar, galat beberapa jam pada umur Bulan.
A3: Masukan | B3: Nilai
A4: Tahun | B4: 2026
A5: Bulan | B5: 12
A6: Tanggal | B6: 9
A7: Jam lokal (jam desimal) | B7: 18
A8: Zona waktu (UTC+) | B8: 7
A10: JD | B10: =DATE(B4,B5,B6)+B7/24-B8/24+2415018.5
A11: k perkiraan | B11: =(B4+(DATE(B4,B5,B6)-DATE(B4,1,1))/365.25-2000)*12.3685
A12: k bulat | B12: =INT(B11)
A13: JD ijtimak rata-rata (k bulat) | B13: =2451550.09766+29.530588861*B12
A14: k terpakai | B14: =IF(B13>B10,B12-1,B12)
A15: JD ijtimak rata-rata | B15: =2451550.09766+29.530588861*B14
A16: Umur Bulan (hari) | B16: =B10-B15
A17: Umur Bulan (jam) | B17: =B16*24
A18: Elongasi rata-rata (°) | B18: =MOD(B16*360/29.530588861,360)
A19: Iluminasi | B19: =(1-COS(RADIANS(B18)))/2
A20: Iluminasi (%) | B20: =B19*100
A21: Fase | B21: =IF(B18<7,"sekitar ijtimak",IF(B18<90,"sabit muda",IF(B18<180,"cembung awal",IF(B18<270,"cembung akhir",IF(B18<353,"sabit tua","menjelang ijtimak")))))
A22: Ijtimak rata-rata (waktu lokal) | B22: =B15-2415018.5+B8/24

Sheet Bulan
A1: Bulan | B1: Posisi geosentris Bulan dengan 60 + 60 suku Meeus (ELP-2000/82 ringkas).
A2: Sumber rumus: Teori ELP-2000/82 (Chapront-Touzé & Chapront, Biro Bujur Paris, 1983), versi 60 + 60 suku dari Meeus (1998, bab 47). Ketelitian: Bujur Bulan sekitar 10″, lintang sekitar 4″.
A3: Masukan | B3: Nilai
A4: JD (UT) | B4: =DataHilal!B31 | E4: D | F4: M | G4: M' | H4: F | I4: Σl | J4: Σr | L4: D | M4: M | N4: M' | O4: F | P4: Σb
A5: ΔT (detik) | B5: =DataHilal!B11 | E5: 0 | F5: 0 | G5: 1 | H5: 0 | I5: 6288774 | J5: -20905355 | L5: 0 | M5: 0 | N5: 0 | O5: 1 | P5: 5128122
A6: JDE | B6: =B4+B5/86400 | E6: 2 | F6: 0 | G6: -1 | H6: 0 | I6: 1274027 | J6: -3699111 | L6: 0 | M6: 0 | N6: 1 | O6: 1 | P6: 280602
A7: T (abad Julian) | B7: =(B6-2451545)/36525 | E7: 2 | F7: 0 | G7: 0 | H7: 0 | I7: 658314 | J7: -2955968 | L7: 0 | M7: 0 | N7: 1 | O7: -1 | P7: 277693
E8: 0 | F8: 0 | G8: 2 | H8: 0 | I8: 213618 | J8: -569925 | L8: 2 | M8: 0 | N8: 0 | O8: -1 | P8: 173237
E9: 0 | F9: 1 | G9: 0 | H9: 0 | I9: -185116 | J9: 48888 | L9: 2 | M9: 0 | N9: -1 | O9: 1 | P9: 55413
A10: L' (°) | B10: =MOD(218.3164477+481267.88123421*B7-0.0015786*B7^2+B7^3/538841-B7^4/65194000,360) | E10: 0 | F10: 0 | G10: 0 | H10: 2 | I10: -114332 | J10: -3149 | L10: 2 | M10: 0 | N10: -1 | O10: -1 | P10: 46271
A11: D (°) | B11: =MOD(297.8501921+445267.1114034*B7-0.0018819*B7^2+B7^3/545868-B7^4/113065000,360) | E11: 2 | F11: 0 | G11: -2 | H11: 0 | I11: 58793 | J11: 246158 | L11: 2 | M11: 0 | N11: 0 | O11: 1 | P11: 32573
A12: M (°) | B12: =MOD(357.5291092+35999.0502909*B7-0.0001536*B7^2+B7^3/24490000,360) | E12: 2 | F12: -1 | G12: -1 | H12: 0 | I12: 57066 | J12: -152138 | L12: 0 | M12: 0 | N12: 2 | O12: 1 | P12: 17198
A13: M' (°) | B13: =MOD(134.9633964+477198.8675055*B7+0.0087414*B7^2+B7^3/69699-B7^4/14712000,360) | E13: 2 | F13: 0 | G13: 1 | H13: 0 | I13: 53322 | J13: -170733 | L13: 2 | M13: 0 | N13: 1 | O13: -1 | P13: 9266
A14: F (°) | B14: =MOD(93.272095+483202.0175233*B7-0.0036539*B7^2-B7^3/3526000+B7^4/863310000,360) | E14: 2 | F14: -1 | G14: 0 | H14: 0 | I14: 45758 | J14: -204586 | L14: 0 | M14: 0 | N14: 2 | O14: -1 | P14: 8822
A15: E | B15: =1-0.002516*B7-0.0000074*B7^2 | E15: 0 | F15: 1 | G15: -1 | H15: 0 | I15: -40923 | J15: -129620 | L15: 2 | M15: -1 | N15: 0 | O15: -1 | P15: 8216
A16: A1 (°) | B16: =MOD(119.75+131.849*B7,360) | E16: 1 | F16: 0 | G16: 0 | H16: 0 | I16: -34720 | J16: 108743 | L16: 2 | M16: 0 | N16: -2 | O16: -1 | P16: 4324
A17: A2 (°) | B17: =MOD(53.09+479264.29*B7,360) | E17: 0 | F17: 1 | G17: 1 | H17: 0 | I17: -30383 | J17: 104755 | L17: 2 | M17: 0 | N17: 1 | O17: 1 | P17: 4200
A18: A3 (°) | B18: =MOD(313.45+481266.484*B7,360) | E18: 2 | F18: 0 | G18: 0 | H18: -2 | I18: 15327 | J18: 10321 | L18: 2 | M18: 1 | N18: 0 | O18: -1 | P18: -3359
E19: 0 | F19: 0 | G19: 1 | H19: 2 | I19: -12528 | J19: 0 | L19: 2 | M19: -1 | N19: -1 | O19: 1 | P19: 2463
A20: Σl (10⁻⁶ °) | B20: =SUMPRODUCT(I5:I64,SIN(RADIANS(E5:E64*$B$11+F5:F64*$B$12+G5:G64*$B$13+H5:H64*$B$14)),$B$15^ABS(F5:F64))+3958*SIN(RADIANS(B16))+1962*SIN(RADIANS(B10-B14))+318*SIN(RADIANS(B17)) | E20: 0 | F20: 0 | G20: 1 | H20: -2 | I20: 10980 | J20: 79661 | L20: 2 | M20: -1 | N20: 0 | O20: 1 | P20: 2211
A21: Σr (10⁻³ km) | B21: =SUMPRODUCT(J5:J64,COS(RADIANS(E5:E64*$B$11+F5:F64*$B$12+G5:G64*$B$13+H5:H64*$B$14)),$B$15^ABS(F5:F64)) | E21: 4 | F21: 0 | G21: -1 | H21: 0 | I21: 10675 | J21: -34782 | L21: 2 | M21: -1 | N21: -1 | O21: -1 | P21: 2065
A22: Σb (10⁻⁶ °) | B22: =SUMPRODUCT(P5:P64,SIN(RADIANS(L5:L64*$B$11+M5:M64*$B$12+N5:N64*$B$13+O5:O64*$B$14)),$B$15^ABS(M5:M64))-2235*SIN(RADIANS(B10))+382*SIN(RADIANS(B18))+175*SIN(RADIANS(B16-B14))+175*SIN(RADIANS(B16+B14))+127*SIN(RADIANS(B10-B13))-115*SIN(RADIANS(B10+B13)) | E22: 0 | F22: 0 | G22: 3 | H22: 0 | I22: 10034 | J22: -23210 | L22: 0 | M22: 1 | N22: -1 | O22: -1 | P22: -1870
E23: 4 | F23: 0 | G23: -2 | H23: 0 | I23: 8548 | J23: -21636 | L23: 4 | M23: 0 | N23: -1 | O23: -1 | P23: 1828
A24: λ geosentris (°) | B24: =MOD(B10+B20/1000000,360) | E24: 2 | F24: 1 | G24: -1 | H24: 0 | I24: -7888 | J24: 24208 | L24: 0 | M24: 1 | N24: 0 | O24: 1 | P24: -1794
A25: β (°) | B25: =B22/1000000 | E25: 2 | F25: 1 | G25: 0 | H25: 0 | I25: -6766 | J25: 30824 | L25: 0 | M25: 0 | N25: 0 | O25: 3 | P25: -1749
A26: Jarak Δ (km) | B26: =385000.56+B21/1000 | E26: 1 | F26: 0 | G26: -1 | H26: 0 | I26: -5163 | J26: -8379 | L26: 0 | M26: 1 | N26: -1 | O26: 1 | P26: -1565
A27: Paralaks π (°) | B27: =DEGREES(ASIN(6378.14/B26)) | E27: 1 | F27: 1 | G27: 0 | H27: 0 | I27: 4987 | J27: -16675 | L27: 1 | M27: 0 | N27: 0 | O27: 1 | P27: -1491
A28: Semidiameter (°) | B28: =0.272481*B27 | E28: 2 | F28: -1 | G28: 1 | H28: 0 | I28: 4036 | J28: -12831 | L28: 0 | M28: 1 | N28: 1 | O28: 1 | P28: -1475
E29: 2 | F29: 0 | G29: 2 | H29: 0 | I29: 3994 | J29: -10445 | L29: 0 | M29: 1 | N29: 1 | O29: -1 | P29: -1410
A30: Ω (°) | B30: =125.04452-1934.136261*B7 | E30: 4 | F30: 0 | G30: 0 | H30: 0 | I30: 3861 | J30: -11650 | L30: 0 | M30: 1 | N30: 0 | O30: -1 | P30: -1344
A31: Δψ (°) | B31: =(-17.2*SIN(RADIANS(B30))-1.32*SIN(RADIANS(2*(280.4665+36000.7698*B7)))-0.23*SIN(RADIANS(2*(218.3165+481267.8813*B7)))+0.21*SIN(RADIANS(2*B30)))/3600 | E31: 2 | F31: 0 | G31: -3 | H31: 0 | I31: 3665 | J31: 14403 | L31: 1 | M31: 0 | N31: 0 | O31: -1 | P31: -1335
A32: ε (°) | B32: =23+26/60+(21.448-46.815*B7)/3600+(9.2*COS(RADIANS(B30))+0.57*COS(RADIANS(2*(280.4665+36000.7698*B7))))/3600 | E32: 0 | F32: 1 | G32: -2 | H32: 0 | I32: -2689 | J32: -7003 | L32: 0 | M32: 0 | N32: 3 | O32: 1 | P32: 1107
A33: λ tampak (°) | B33: =B24+B31 | E33: 2 | F33: 0 | G33: -1 | H33: 2 | I33: -2602 | J33: 0 | L33: 4 | M33: 0 | N33: 0 | O33: -1 | P33: 1021
A34: α (°) | B34: =MOD(DEGREES(ATAN2(COS(RADIANS(B33)),SIN(RADIANS(B33))*COS(RADIANS(B32))-TAN(RADIANS(B25))*SIN(RADIANS(B32)))),360) | E34: 2 | F34: -1 | G34: -2 | H34: 0 | I34: 2390 | J34: 10056 | L34: 4 | M34: 0 | N34: -1 | O34: 1 | P34: 833
A35: δ (°) | B35: =DEGREES(ASIN(SIN(RADIANS(B25))*COS(RADIANS(B32))+COS(RADIANS(B25))*SIN(RADIANS(B32))*SIN(RADIANS(B33)))) | E35: 1 | F35: 0 | G35: 1 | H35: 0 | I35: -2348 | J35: 6322 | L35: 0 | M35: 0 | N35: 1 | O35: -3 | P35: 777
E36: 2 | F36: -2 | G36: 0 | H36: 0 | I36: 2236 | J36: -9884 | L36: 4 | M36: 0 | N36: -2 | O36: 1 | P36: 671
E37: 0 | F37: 1 | G37: 2 | H37: 0 | I37: -2120 | J37: 5751 | L37: 2 | M37: 0 | N37: 0 | O37: -3 | P37: 607
E38: 0 | F38: 2 | G38: 0 | H38: 0 | I38: -2069 | J38: 0 | L38: 2 | M38: 0 | N38: 2 | O38: -1 | P38: 596
E39: 2 | F39: -2 | G39: -1 | H39: 0 | I39: 2048 | J39: -4950 | L39: 2 | M39: -1 | N39: 1 | O39: -1 | P39: 491
E40: 2 | F40: 0 | G40: 1 | H40: -2 | I40: -1773 | J40: 4130 | L40: 2 | M40: 0 | N40: -2 | O40: 1 | P40: -451
...

Sheet KoreksiHilal
A1: KoreksiHilal | B1: Tangga koreksi tinggi hilal: paralaks, refraksi, semidiameter, kerendahan ufuk.
A2: Sumber rumus: Paralaks dari jarak Bulan; refraksi Sæmundsson (1986); kerendahan ufuk 1,76′√H. Ketelitian: Baik untuk udara standar; refraksi nyata dekat ufuk bisa berbeda 0,1°–0,5°.
A3: Masukan | B3: Nilai
A4: Tinggi geosentris pusat Bulan (°) | B4: 3.21
A5: Jarak Bumi–Bulan (km) | B5: 405254.8
A6: Suhu udara (°C) | B6: 10
A7: Tekanan udara (mbar) | B7: 1010
A8: Tinggi mata di atas ufuk (m) | B8: 700
A10: Paralaks horizontal π (°) | B10: =DEGREES(ASIN(6378.14/B5))
A11: Tinggi toposentris (°) | B11: =DEGREES(ATAN((SIN(RADIANS(B4))-SIN(RADIANS(B10)))/COS(RADIANS(B4))))
A12: Paralaks dalam tinggi (°) | B12: =B4-B11
A13: Refraksi (°) | B13: =1.02/TAN(RADIANS(B11+10.3/(B11+5.11)))/60*B7/1010*283/(273+B6)
A14: Semidiameter toposentris (°) | B14: =0.272481*B10*(1+SIN(RADIANS(B11))*SIN(RADIANS(B10)))
A15: Kerendahan ufuk (°) | B15: =1.76*SQRT(B8)/60
A17: Tinggi tampak pusat Bulan (°) | B17: =B11+B13
A18: Tinggi tampak piringan atas (°) | B18: =B17+B14
A19: Tinggi mar'i piringan atas (°) | B19: =B18+B15

Sheet Ijtimak
A1: Ijtimak | B1: Saat ijtimak dengan metode Meeus (rata-rata + 25 suku periodik + 14 suku planet).
A2: Sumber rumus: Meeus (1998, bab 49): ijtimak rata-rata + 25 suku periodik + 14 suku planet. Ketelitian: Contoh Syawal 1447 H berselisih 7 detik dari BMKG.
A3: Masukan | B3: Nilai
A4: Tahun desimal | B4: 2026.94 | E4: Koef. | F4: Pangkat E | G4: M | H4: M' | I4: F | J4: Ω | L4: A₀ (°) | M4: A₁ (°/k) | N4: Amplitudo (10⁻⁶ hari)
A5: ΔT (detik) | B5: 69.3 | E5: -0.4072 | F5: 0 | G5: 0 | H5: 1 | I5: 0 | J5: 0 | L5: 299.77 | M5: 0.107408 | N5: 325
A6: Zona waktu (UTC+) | B6: 7 | E6: 0.17241 | F6: 1 | G6: 1 | H6: 0 | I6: 0 | J6: 0 | L6: 251.88 | M6: 0.016321 | N6: 165
E7: 0.01608 | F7: 0 | G7: 0 | H7: 2 | I7: 0 | J7: 0 | L7: 251.83 | M7: 26.651886 | N7: 164
A8: k (nomor lunasi) | B8: =ROUND((B4-2000)*12.3685,0) | E8: 0.01039 | F8: 0 | G8: 0 | H8: 0 | I8: 2 | J8: 0 | L8: 349.42 | M8: 36.412478 | N8: 126
A9: T | B9: =B8/1236.85 | E9: 0.00739 | F9: 1 | G9: -1 | H9: 1 | I9: 0 | J9: 0 | L9: 84.66 | M9: 18.206239 | N9: 110
A10: JDE₀ (ijtimak rata-rata) | B10: =2451550.09766+29.530588861*B8+0.00015437*B9^2-0.00000015*B9^3+0.00000000073*B9^4 | E10: -0.00514 | F10: 1 | G10: 1 | H10: 1 | I10: 0 | J10: 0 | L10: 141.74 | M10: 53.303771 | N10: 62
A11: E | B11: =1-0.002516*B9-0.0000074*B9^2 | E11: 0.00208 | F11: 2 | G11: 2 | H11: 0 | I11: 0 | J11: 0 | L11: 207.14 | M11: 2.453732 | N11: 60
A12: M (°) | B12: =MOD(2.5534+29.1053567*B8-0.0000014*B9^2-0.00000011*B9^3,360) | E12: -0.00111 | F12: 0 | G12: 0 | H12: 1 | I12: -2 | J12: 0 | L12: 154.84 | M12: 7.30686 | N12: 56
A13: M' (°) | B13: =MOD(201.5643+385.81693528*B8+0.0107582*B9^2+0.00001238*B9^3-0.000000058*B9^4,360) | E13: -0.00057 | F13: 0 | G13: 0 | H13: 1 | I13: 2 | J13: 0 | L13: 34.52 | M13: 27.261239 | N13: 47
A14: F (°) | B14: =MOD(160.7108+390.67050284*B8-0.0016118*B9^2-0.00000227*B9^3+0.000000011*B9^4,360) | E14: 0.00056 | F14: 1 | G14: 1 | H14: 2 | I14: 0 | J14: 0 | L14: 207.19 | M14: 0.121824 | N14: 42
A15: Ω (°) | B15: =MOD(124.7746-1.56375588*B8+0.0020672*B9^2+0.00000215*B9^3,360) | E15: -0.00042 | F15: 0 | G15: 0 | H15: 3 | I15: 0 | J15: 0 | L15: 291.34 | M15: 1.844379 | N15: 40
A16: Δ₁ suku periodik (hari) | B16: =SUMPRODUCT(E5:E29,$B$11^F5:F29,SIN(RADIANS(G5:G29*$B$12+H5:H29*$B$13+I5:I29*$B$14+J5:J29*$B$15))) | E16: 0.00042 | F16: 1 | G16: 1 | H16: 0 | I16: 2 | J16: 0 | L16: 161.72 | M16: 24.198154 | N16: 37
A17: Δ₂ suku planet (hari) | B17: =SUMPRODUCT(N5:N18,SIN(RADIANS(L5:L18+M5:M18*$B$8)))/1000000 | E17: 0.00038 | F17: 1 | G17: 1 | H17: 0 | I17: -2 | J17: 0 | L17: 239.56 | M17: 25.513099 | N17: 35
A18: JDE ijtimak | B18: =B10+B16+B17 | E18: -0.00024 | F18: 1 | G18: -1 | H18: 2 | I18: 0 | J18: 0 | L18: 331.55 | M18: 3.592518 | N18: 23
A19: JD ijtimak (UT) | B19: =B18-B5/86400 | E19: -0.00017 | F19: 0 | G19: 0 | H19: 0 | I19: 0 | J19: 1
A20: Ijtimak (waktu daerah) | B20: =B19-2415018.5+B6/24 | E20: -7e-05 | F20: 0 | G20: 2 | H20: 1 | I20: 0 | J20: 0
E21: 4e-05 | F21: 0 | G21: 0 | H21: 2 | I21: -2 | J21: 0
A22: Bantu: tahun desimal dari bulan Hijriyah | B22: Nilai | E22: 4e-05 | F22: 0 | G22: 3 | H22: 0 | I22: 0 | J22: 0
A23: Tahun Hijriyah | B23: 1448 | E23: 3e-05 | F23: 0 | G23: 1 | H23: 1 | I23: -2 | J23: 0
A24: Bulan Hijriyah (1 = Muharam, …, 12 = Zulhijah) | B24: 7 | E24: 3e-05 | F24: 0 | G24: 0 | H24: 2 | I24: 2 | J24: 0
A25: k untuk ijtimak sebelum bulan itu | B25: =12*(B23-1420)+B24-10 | E25: -3e-05 | F25: 0 | G25: 1 | H25: 1 | I25: 2 | J25: 0
A26: Tahun desimal untuk B4 | B26: =2000+B25/12.3685 | E26: 3e-05 | F26: 0 | G26: -1 | H26: 1 | I26: 2 | J26: 0
E27: -2e-05 | F27: 0 | G27: -1 | H27: 1 | I27: -2 | J27: 0
E28: -2e-05 | F28: 0 | G28: 1 | H28: 3 | I28: 0 | J28: 0
E29: 2e-05 | F29: 0 | G29: 0 | H29: 4 | I29: 0 | J29: 0

Sheet Urfi
A1: Urfi | B1: Konversi tanggal Hijriyah urfi ke Julian Day dan tanggal Masehi.
A2: Sumber rumus: Kalender Hijriyah tabular (siklus 30 tahun, 11 kabisat, pola II) dari tradisi zij Islam. Ketelitian: Pasti; tanggal urfi bisa berbeda 1–2 hari dari awal bulan sebenarnya.
A3: Masukan | B3: Nilai
A4: Tahun Hijriyah (H) | B4: 1448
A5: Bulan Hijriyah (B) | B5: 9
A6: Tanggal (T) | B6: 1
A8: Kabisat? | B8: =IF(MOD(14+11*B4,30)<11,"kabisat (355 hari)","basithah (354 hari)")
A9: Hari tahun-tahun sebelumnya | B9: =354*(B4-1)+INT((3+11*B4)/30)
A10: Hari bulan-bulan sebelumnya | B10: =29*(B5-1)+INT(B5/2)
A11: JD (00.00 UT) | B11: =1948439.5+B9+B10+B6-1
A12: Tanggal Masehi | B12: =B11-2415018.5
A13: Hari | B13: =CHOOSE(MOD(INT(B11+1.5),7)+1,"Ahad","Senin","Selasa","Rabu","Kamis","Jumat","Sabtu")
A14: Pasaran | B14: =CHOOSE(MOD(INT(B11+0.5),5)+1,"Legi","Pahing","Pon","Wage","Kliwon")
A15: Umur bulan ini (hari) | B15: =IF(MOD(B5,2)=1,30,IF(AND(B5=12,MOD(14+11*B4,30)<11),30,29))

Sheet DataHilal
A1: DataHilal | B1: Data hilal saat Matahari terbenam: Matahari (NOAA) + Bulan (sheet Bulan) + ijtimak (sheet Ijtimak).
A2: Sumber rumus: Matahari: algoritma NOAA (Meeus 1998, bab 25); Bulan: sheet Bulan; paralaks dan kerendahan ufuk. Ketelitian: Terbenam Matahari 1 detik, terbenam Bulan 6 detik, elongasi di bawah 0,05° dari BMKG.
A3: Masukan | B3: Nilai
A4: Lintang φ (°) | B4: -6.9312
A5: Bujur λ (°) | B5: 107.7175
A6: Tinggi tempat (m) | B6: 700
A7: Zona waktu (UTC+) | B7: 7
A8: Tahun | B8: 2026
A9: Bulan | B9: 12
A10: Tanggal | B10: 9
A11: ΔT (detik) | B11: 69.3
A13: JD 00.00 waktu lokal | B13: =DATE(B8,B9,B10)+2415018.5-B7/24
A14: Perkiraan terbenam (jam lokal) | B14: 18
A15: JD perkiraan | B15: =B13+B14/24
A16: T | B16: =(B15+B11/86400-2451545)/36525
A17: L₀ Matahari (°) | B17: =MOD(280.46646+36000.76983*B16+0.0003032*B16^2,360)
A18: M Matahari (°) | B18: =357.52911+35999.05029*B16-0.0001537*B16^2
A19: e orbit Bumi | B19: =0.016708634-0.000042037*B16
A20: C (°) | B20: =SIN(RADIANS(B18))*(1.914602-0.004817*B16)+SIN(RADIANS(2*B18))*(0.019993-0.000101*B16)+0.000289*SIN(RADIANS(3*B18))
A21: λ☉ tampak (°) | B21: =B17+B20-0.00569-0.00478*SIN(RADIANS(125.04-1934.136*B16))
A22: ε (°) | B22: =23.439291-0.0130042*B16+0.00256*COS(RADIANS(125.04-1934.136*B16))
A23: δ☉ (°) | B23: =DEGREES(ASIN(SIN(RADIANS(B22))*SIN(RADIANS(B21))))
A24: α☉ (°) | B24: =MOD(DEGREES(ATAN2(COS(RADIANS(B21)),COS(RADIANS(B22))*SIN(RADIANS(B21)))),360)
A25: R (au) | B25: =1.000001018*(1-B19^2)/(1+B19*COS(RADIANS(B18+B20)))
A26: y | B26: =TAN(RADIANS(B22/2))^2
A27: Perata waktu (menit) | B27: =4*DEGREES(B26*SIN(2*RADIANS(B17))-2*B19*SIN(RADIANS(B18))+4*B19*B26*SIN(RADIANS(B18))*COS(2*RADIANS(B17))-0.5*B26^2*SIN(4*RADIANS(B17))-1.25*B19^2*SIN(2*RADIANS(B18)))
A28: h₀ Matahari (°) | B28: =-(0.2666/B25+34/60+1.76*SQRT(B6)/60)
A29: t₀ (°) | B29: =DEGREES(ACOS((SIN(RADIANS(B28))-SIN(RADIANS(B4))*SIN(RADIANS(B23)))/(COS(RADIANS(B4))*COS(RADIANS(B23)))))
A30: Matahari terbenam (jam lokal) | B30: =12-B27/60+(B7*15-B5)/15+B29/15
A31: JD Matahari terbenam (UT) | B31: =B13+B30/24
A32: Matahari terbenam | B32: =B30/24
A34: α☾ (°) | B34: =Bulan!B34
A35: δ☾ (°) | B35: =Bulan!B35
A36: π Bulan (°) | B36: =Bulan!B27
A37: SD Bulan (°) | B37: =Bulan!B28
A38: Waktu sideris Greenwich (°) | B38: =MOD(280.46061837+360.98564736629*(B31-2451545),360)
A39: Sudut waktu Bulan H☾ (°) | B39: =MOD(B38+B5-B34+180,360)-180
A40: Tinggi geosentris Bulan (°) | B40: =DEGREES(ASIN(SIN(RADIANS(B4))*SIN(RADIANS(B35))+COS(RADIANS(B4))*COS(RADIANS(B35))*COS(RADIANS(B39))))
A41: Tinggi hilal toposentris (°) | B41: =DEGREES(ATAN((SIN(RADIANS(B40))-SIN(RADIANS(B36)))/COS(RADIANS(B40))))
A42: Azimut Bulan (°) | B42: =MOD(DEGREES(ATAN2(COS(RADIANS(B4))*SIN(RADIANS(B35))-SIN(RADIANS(B4))*COS(RADIANS(B35))*COS(RADIANS(B39)),-COS(RADIANS(B35))*SIN(RADIANS(B39)))),360)
...

Sheet Kriteria
A1: Kriteria | B1: Pemeriksaan kriteria visibilitas hilal dari data sheet DataHilal.
A2: Sumber rumus: Wujudul hilal, MABIMS lama dan baru (2021), Danjon (1932), Odeh (2004), Yallop (1997), Turki 2016. Ketelitian: Tergantung data hilal; kasus di dekat batas kriteria perlu dicocokkan dengan data resmi.
A3: Data | B3: Nilai
A4: Tinggi hilal toposentris (°) | B4: =DataHilal!B41
A5: Elongasi geosentris (°) | B5: =DataHilal!B47
A6: Elongasi toposentris (°) | B6: =DataHilal!B48
A7: Umur Bulan (jam) | B7: =DataHilal!B52
A8: Lag (menit) | B8: =DataHilal!B55
A9: ARCV (°) | B9: =DataHilal!B51
A10: Lebar sabit W (′) | B10: =DataHilal!B50
A12: Wujudul hilal | B12: =IF(AND(B7>0,B8>0),"terpenuhi","tidak")
A13: MABIMS lama (2-3-8) | B13: =IF(AND(B7>0,B4>=2,OR(B5>=3,B7>=8)),"terpenuhi","tidak")
A14: MABIMS baru (3–6,4) | B14: =IF(AND(B7>0,B4>=3,B6>=6.4),"terpenuhi","tidak")
A15: Batas Danjon (7°) | B15: =IF(B6>=7,"terpenuhi","tidak")
A16: V (Odeh) | B16: =B9-(-0.1018*B10^3+0.7319*B10^2-6.3226*B10+7.1651)
A17: Zona Odeh | B17: =IF(B16>=5.65,"A",IF(B16>=2,"B",IF(B16>=-0.96,"C","D")))
A18: q (Yallop) | B18: =(B9-(11.8371-6.3226*B10+0.7319*B10^2-0.1018*B10^3))/10
A19: Kelas Yallop | B19: =IF(B18>0.216,"A",IF(B18>-0.014,"B",IF(B18>-0.16,"C",IF(B18>-0.232,"D",IF(B18>-0.293,"E","F")))))
A20: Turki 2016 di tempat ini | B20: =IF(AND(B7>0,DataHilal!B40>=5,B5>=8),"terpenuhi","tidak")

Sheet Rukyat
A1: Rukyat | B1: Tabel panduan posisi hilal setiap 4 menit sesudah Matahari terbenam, dengan massa udara dan ekstingsi.
A2: Sumber rumus: Massa udara Kasten & Young (1989); ekstingsi dengan koefisien k. Ketelitian: Perkiraan; koefisien ekstingsi dipilih sendiri.
A3: Data | B3: Nilai
A4: Tinggi hilal saat terbenam (°) | B4: =DataHilal!B41
A5: Lag (menit) | B5: =DataHilal!B55
A6: Azimut Bulan (°) | B6: =DataHilal!B42
A7: Matahari terbenam | B7: =DataHilal!B32
A8: Koefisien ekstingsi k | B8: 0.3
A9: Laju turun hilal (°/menit) | B9: =(B4+DataHilal!B37+34/60+1.76*SQRT(DataHilal!B6)/60)/B5
A11: Menit | B11: Jam | C11: Tinggi (°) | D11: Massa udara | E11: Cahaya tersisa (%)
A12: 0 | B12: =$B$7+A12/1440 | C12: =$B$4-$B$9*A12 | D12: =IF(C12>0,1/(SIN(RADIANS(C12))+0.50572*(C12+6.07995)^-1.6364),"—") | E12: =IF(ISNUMBER(D12),100*10^(-0.4*$B$8*D12),"—")
A13: 4 | B13: =$B$7+A13/1440 | C13: =$B$4-$B$9*A13 | D13: =IF(C13>0,1/(SIN(RADIANS(C13))+0.50572*(C13+6.07995)^-1.6364),"—") | E13: =IF(ISNUMBER(D13),100*10^(-0.4*$B$8*D13),"—")
A14: 8 | B14: =$B$7+A14/1440 | C14: =$B$4-$B$9*A14 | D14: =IF(C14>0,1/(SIN(RADIANS(C14))+0.50572*(C14+6.07995)^-1.6364),"—") | E14: =IF(ISNUMBER(D14),100*10^(-0.4*$B$8*D14),"—")
A15: 12 | B15: =$B$7+A15/1440 | C15: =$B$4-$B$9*A15 | D15: =IF(C15>0,1/(SIN(RADIANS(C15))+0.50572*(C15+6.07995)^-1.6364),"—") | E15: =IF(ISNUMBER(D15),100*10^(-0.4*$B$8*D15),"—")
A16: 16 | B16: =$B$7+A16/1440 | C16: =$B$4-$B$9*A16 | D16: =IF(C16>0,1/(SIN(RADIANS(C16))+0.50572*(C16+6.07995)^-1.6364),"—") | E16: =IF(ISNUMBER(D16),100*10^(-0.4*$B$8*D16),"—")

Sheet Gerhana
A1: Gerhana | B1: Prediksi gerhana Matahari dan Bulan dengan metode Meeus (bab 54): saat puncak, γ, u, jenis, magnitudo, dan lama setengah fase.
A2: Sumber rumus: Meeus (1998, bab 54): γ, u, magnitudo, dan setengah fase. Ketelitian: Jenis gerhana hampir selalu benar; puncak dan kontak berselisih beberapa menit dari NASA.
A3: Masukan | B3: Nilai
A4: Tahun | B4: 2026
A5: Bulan | B5: 8
A6: Tanggal | B6: 12
A7: Jenis (0 = Matahari, 1 = Bulan) | B7: 0
A8: ΔT (detik) | B8: 69.3
A10: k perkiraan | B10: =(B4+(DATE(B4,B5,B6)-DATE(B4,1,1))/365.25-2000)*12.3685
A11: k | B11: =ROUND(B10-B7/2,0)+B7/2
A12: T | B12: =B11/1236.85
A13: F (°) | B13: =MOD(160.7108+390.67050284*B11-0.0016118*B12^2-0.00000227*B12^3+0.000000011*B12^4,360)
A14: Saringan F | B14: =IF(ABS(SIN(RADIANS(B13)))>0.36,"tidak ada gerhana","mungkin ada gerhana")
A15: JDE rata-rata | B15: =2451550.09766+29.530588861*B11+0.00015437*B12^2-0.00000015*B12^3+0.00000000073*B12^4
A16: M (°) | B16: =MOD(2.5534+29.1053567*B11-0.0000014*B12^2-0.00000011*B12^3,360)
A17: M' (°) | B17: =MOD(201.5643+385.81693528*B11+0.0107582*B12^2+0.00001238*B12^3-0.000000058*B12^4,360)
A18: Ω (°) | B18: =MOD(124.7746-1.56375588*B11+0.0020672*B12^2+0.00000215*B12^3,360)
A19: E | B19: =1-0.002516*B12-0.0000074*B12^2
A20: F₁ (°) | B20: =B13-0.02665*SIN(RADIANS(B18))
A21: A₁ (°) | B21: =299.77+0.107408*B11-0.009173*B12^2
A22: Koreksi (hari) | B22: =IF(B7=1,-0.4065,-0.4075)*SIN(RADIANS(B17))+IF(B7=1,0.1727,0.1721)*B19*SIN(RADIANS(B16))+0.0161*SIN(RADIANS(2*B17))-0.0097*SIN(RADIANS(2*B20))+0.0073*B19*SIN(RADIANS(B17-B16))-0.005*B19*SIN(RADIANS(B17+B16))-0.0023*SIN(RADIANS(B17-2*B20))+0.0021*B19*SIN(RADIANS(2*B16))+0.0012*SIN(RADIANS(B17+2*B20))+0.0006*B19*SIN(RADIANS(2*B17+B16))-0.0004*SIN(RADIANS(3*B17))-0.0003*B19*SIN(RADIANS(B16+2*B20))+0.0003*SIN(RADIANS(B21))-0.0002*B19*SIN(RADIANS(B16-2*B20))-0.0002*B19*SIN(RADIANS(2*B17-B16))-0.0002*SIN(RADIANS(B18))
A23: JDE puncak | B23: =B15+B22
A24: JD puncak (UT) | B24: =B23-B8/86400
A25: Puncak gerhana (UT) | B25: =B24-2415018.5
A26: P | B26: =0.207*B19*SIN(RADIANS(B16))+0.0024*B19*SIN(RADIANS(2*B16))-0.0392*SIN(RADIANS(B17))+0.0116*SIN(RADIANS(2*B17))-0.0073*B19*SIN(RADIANS(B17+B16))+0.0067*B19*SIN(RADIANS(B17-B16))+0.0118*SIN(RADIANS(2*B20))
A27: Q | B27: =5.2207-0.0048*B19*COS(RADIANS(B16))+0.002*B19*COS(RADIANS(2*B16))-0.3299*COS(RADIANS(B17))-0.006*B19*COS(RADIANS(B17+B16))+0.0041*B19*COS(RADIANS(B17-B16))
A28: W | B28: =ABS(COS(RADIANS(B20)))
A29: γ (jari-jari Bumi) | B29: =(B26*COS(RADIANS(B20))+B27*SIN(RADIANS(B20)))*(1-0.0048*B28)
A30: u | B30: =0.0059+0.0046*B19*COS(RADIANS(B16))-0.0182*COS(RADIANS(B17))+0.0004*COS(RADIANS(2*B17))-0.0005*COS(RADIANS(B16+B17))
A31: Jenis gerhana | B31: =IF(ABS(SIN(RADIANS(B13)))>0.36,"tidak ada",IF(B7=0,IF(ABS(B29)>1.5433+B30,"tidak ada",IF(ABS(B29)>=0.9972,"Matahari sebagian",IF(B30<0,"Matahari total",IF(B30>0.0047,"Matahari cincin",IF(B30<0.00464*SQRT(1-B29^2),"Matahari hibrida","Matahari cincin"))))),IF(B33<=0,"tidak ada",IF(B34<=0,"Bulan penumbra",IF(B34<1,"Bulan sebagian","Bulan total")))))
A32: Magnitudo (Matahari, tidak sentral) | B32: =IF(AND(B7=0,ABS(B29)>=0.9972),(1.5433+B30-ABS(B29))/(0.5461+2*B30),"—")
A33: Magnitudo penumbra (Bulan) | B33: =IF(B7=1,(1.5573+B30-ABS(B29))/0.545,"—")
A34: Magnitudo umbra (Bulan) | B34: =IF(B7=1,(1.0128-B30-ABS(B29))/0.545,"—")
A35: n | B35: =0.5458+0.04*COS(RADIANS(B17))
A36: Setengah fase penumbra (menit) | B36: =IF(B7=1,60/B35*SQRT(MAX(0,(1.5573+B30)^2-B29^2)),"—")
A37: Setengah fase sebagian (menit) | B37: =IF(AND(B7=1,B34>0),60/B35*SQRT(MAX(0,(1.0128-B30)^2-B29^2)),"—")
A38: Setengah fase total (menit) | B38: =IF(AND(B7=1,B34>=1),60/B35*SQRT(MAX(0,(0.4678-B30)^2-B29^2)),"—")

Sheet GerhanaBulan
A1: GerhanaBulan | B1: Jadwal kontak gerhana Bulan dari saat puncak dan lama setengah fase (metode Meeus, sheet Gerhana).
A2: Sumber rumus: Meeus (1998, bab 54): γ, u, magnitudo, dan setengah fase. Ketelitian: Jenis gerhana hampir selalu benar; puncak dan kontak berselisih beberapa menit dari NASA.
A3: Masukan | B3: Nilai
A4: JD puncak (UT) | B4: 2461103
A5: Setengah fase penumbra (menit) | B5: 167.88
A6: Setengah fase sebagian (menit) | B6: 102.64
A7: Setengah fase total (menit) | B7: 28.73
A8: Zona waktu (UTC+) | B8: 7
A10: Kontak | B10: Jam UT | C10: Jam daerah
A11: P1 awal penumbra | B11: =MOD($B$4+0.5-$B$5/1440,1) | C11: =IF(ISNUMBER(B11),MOD(B11+$B$8/24,1),"—")
A12: U1 awal sebagian | B12: =IF($B$6>0,MOD($B$4+0.5-$B$6/1440,1),"—") | C12: =IF(ISNUMBER(B12),MOD(B12+$B$8/24,1),"—")
A13: U2 awal total | B13: =IF($B$7>0,MOD($B$4+0.5-$B$7/1440,1),"—") | C13: =IF(ISNUMBER(B13),MOD(B13+$B$8/24,1),"—")
A14: Puncak | B14: =MOD($B$4+0.5,1) | C14: =IF(ISNUMBER(B14),MOD(B14+$B$8/24,1),"—")
A15: U3 akhir total | B15: =IF($B$7>0,MOD($B$4+0.5+$B$7/1440,1),"—") | C15: =IF(ISNUMBER(B15),MOD(B15+$B$8/24,1),"—")
A16: U4 akhir sebagian | B16: =IF($B$6>0,MOD($B$4+0.5+$B$6/1440,1),"—") | C16: =IF(ISNUMBER(B16),MOD(B16+$B$8/24,1),"—")
A17: P4 akhir penumbra | B17: =MOD($B$4+0.5+$B$5/1440,1) | C17: =IF(ISNUMBER(B17),MOD(B17+$B$8/24,1),"—")
A19: Tanggal puncak (waktu daerah) | B19: =B4-2415018.5+B8/24
A20: Lama fase total (menit) | B20: =2*B7
A21: Lama fase umbra (menit) | B21: =2*B6
A22: Lama seluruh gerhana (menit) | B22: =2*B5

Sheet GerhanaMatahari
A1: GerhanaMatahari | B1: Magnitudo dan obskurasi gerhana Matahari di suatu tempat dari semidiameter dan jarak sudut pusat Matahari–Bulan.
A2: Sumber rumus: Geometri dua lingkaran yang beririsan. Ketelitian: Pasti, asalkan semidiameter dan jarak sudut benar (dari aplikasi).
A3: Masukan | B3: Nilai
A4: Semidiameter Matahari s☉ (′) | B4: 15.9227
A5: Semidiameter toposentris Bulan s☾ (′) | B5: 16.1438
A6: Jarak sudut pusat σ (′) | B6: 16.2698
A8: Magnitudo | B8: =(B4+B5-B6)/(2*B4)
A9: Keadaan | B9: =IF(B6>=B4+B5,"tidak terjadi",IF(B6<=B5-B4,"total",IF(B6<=B4-B5,"cincin","sebagian")))
A10: α₁ (radian) | B10: =IF(AND(B6<B4+B5,B6>ABS(B5-B4)),ACOS((B6^2+B4^2-B5^2)/(2*B6*B4)),0)
A11: α₂ (radian) | B11: =IF(AND(B6<B4+B5,B6>ABS(B5-B4)),ACOS((B6^2+B5^2-B4^2)/(2*B6*B5)),0)
A12: Luas irisan (′²) | B12: =B4^2*(B10-SIN(2*B10)/2)+B5^2*(B11-SIN(2*B11)/2)
A13: Obskurasi | B13: =IF(B6>=B4+B5,0,IF(B6<=B5-B4,1,IF(B6<=B4-B5,(B5/B4)^2,B12/(PI()*B4^2))))
A14: Obskurasi (%) | B14: =B13*100
